{"table": "orderBookL2", "action": "delete", "data": [{"symbol": "XBTUSD", "id": 15597202200, "side": "Sell"}, {"symbol": "XBTUSD", "id": 15599752800, "side": "Buy"}]}
{"table": "orderBookL2", "action": "insert", "data": [{"symbol": "XBTUSD", "id": 15597629100, "side": "Sell", "size": 905, "price": 23709}, {"symbol": "XBTUSD", "id": 15599780800, "side": "Buy", "size": 679, "price": 2192}]}
{"table": "orderBookL2", "action": "delete", "data": [{"symbol": "XBTUSD", "id": 15595976700, "side": "Sell"}, {"symbol": "XBTUSD", "id": 15599777300, "side": "Buy"}]}
{"table": "orderBookL2", "action": "insert", "data": [{"symbol": "XBTUSD", "id": 15595198900, "side": "Sell", "size": 436, "price": 48011}, {"symbol": "XBTUSD", "id": 15599776700, "side": "Buy", "size": 879, "price": 2233}]}
{"table": "orderBookL2", "action": "update", "data": [{"symbol": "XBTUSD", "id": 15599116900, "side": "Buy", "size": 16095}]}
{"table": "orderBookL2", "action": "delete", "data": [{"symbol": "XBTUSD", "id": 15595130400, "side": "Sell"}, {"symbol": "XBTUSD", "id": 15599793700, "side": "Buy"}]}
{"table": "orderBookL2", "action": "insert", "data": [{"symbol": "XBTUSD", "id": 15595818600, "side": "Sell", "size": 516, "price": 41814}, {"symbol": "XBTUSD", "id": 15599806600, "side": "Buy", "size": 596, "price": 1934}]}
{"table": "orderBookL2", "action": "update", "data": [{"symbol": "XBTUSD", "id": 15599117000, "side": "Buy", "size": 459}]}
{"table": "orderBookL2", "action": "insert", "data": [{"symbol": "XBTUSD", "id": 15599057500, "side": "Sell", "size": 100, "price": 9425}]}
{"table": "orderBookL2", "action": "delete", "data": [{"symbol": "XBTUSD", "id": 15595808700, "side": "Sell"}, {"symbol": "XBTUSD", "id": 15599759500, "side": "Buy"}]}
{"table": "orderBookL2", "action": "insert", "data": [{"symbol": "XBTUSD", "id": 15596370100, "side": "Sell", "size": 85, "price": 36299}, {"symbol": "XBTUSD", "id": 15599770300, "side": "Buy", "size": 40, "price": 2297}]}
{"table": "orderBookL2", "action": "delete", "data": [{"symbol": "XBTUSD", "id": 15595818600, "side": "Sell"}, {"symbol": "XBTUSD", "id": 15599806600, "side": "Buy"}]}
{"table": "orderBookL2", "action": "insert", "data": [{"symbol": "XBTUSD", "id": 15597766400, "side": "Sell", "size": 72, "price": 22336}, {"symbol": "XBTUSD", "id": 15599814400, "side": "Buy", "size": 543, "price": 1856}]}
{"table": "orderBookL2", "action": "delete", "data": [{"symbol": "XBTUSD", "id": 15595198900, "side": "Sell"}, {"symbol": "XBTUSD", "id": 15599776700, "side": "Buy"}]}
{"table": "orderBookL2", "action": "insert", "data": [{"symbol": "XBTUSD", "id": 15595794300, "side": "Sell", "size": 376, "price": 42057}, {"symbol": "XBTUSD", "id": 15599753500, "side": "Buy", "size": 730, "price": 2465}]}
{"table": "orderBookL2", "action": "delete", "data": [{"symbol": "XBTUSD", "id": 15597629100, "side": "Sell"}, {"symbol": "XBTUSD", "id": 15599780800, "side": "Buy"}]}
{"table": "orderBookL2", "action": "insert", "data": [{"symbol": "XBTUSD", "id": 15596541300, "side": "Sell", "size": 470, "price": 34587}, {"symbol": "XBTUSD", "id": 15599848600, "side": "Buy", "size": 205, "price": 1514}]}
{"table": "orderBookL2", "action": "delete", "data": [{"symbol": "XBTUSD", "id": 15597354600, "side": "Sell"}, {"symbol": "XBTUSD", "id": 15599812600, "side": "Buy"}]}
{"table": "orderBookL2", "action": "insert", "data": [{"symbol": "XBTUSD", "id": 15598504600, "side": "Sell", "size": 102, "price": 14954}, {"symbol": "XBTUSD", "id": 15599843000, "side": "Buy", "size": 645, "price": 1570}]}
{"table": "orderBookL2", "action": "delete", "data": [{"symbol": "XBTUSD", "id": 15599116150, "side": "Sell"}]}
{"table": "orderBookL2", "action": "update", "data": [{"symbol": "XBTUSD", "id": 15599117100, "side": "Buy", "size": 125}]}
{"table": "orderBookL2", "action": "update", "data": [{"symbol": "XBTUSD", "id": 15599116200, "side": "Sell", "size": 3219}]}
{"table": "orderBookL2", "action": "delete", "data": [{"symbol": "XBTUSD", "id": 15596370100, "side": "Sell"}, {"symbol": "XBTUSD", "id": 15599770300, "side": "Buy"}]}
{"table": "orderBookL2", "action": "insert", "data": [{"symbol": "XBTUSD", "id": 15597240000, "side": "Sell", "size": 211, "price": 27600}, {"symbol": "XBTUSD", "id": 15599774500, "side": "Buy", "size": 608, "price": 2255}]}
{"table": "orderBookL2", "action": "delete", "data": [{"symbol": "XBTUSD", "id": 15597766400, "side": "Sell"}, {"symbol": "XBTUSD", "id": 15599814400, "side": "Buy"}]}
{"table": "orderBookL2", "action": "insert", "data": [{"symbol": "XBTUSD", "id": 15598143100, "side": "Sell", "size": 481, "price": 18569}, {"symbol": "XBTUSD", "id": 15599837000, "side": "Buy", "size": 767, "price": 1630}]}
{"table": "orderBookL2", "action": "delete", "data": [{"symbol": "XBTUSD", "id": 15599113300, "side": "Sell"}]}
{"table": "orderBookL2", "action": "delete", "data": [{"symbol": "XBTUSD", "id": 15596541300, "side": "Sell"}, {"symbol": "XBTUSD", "id": 15599848600, "side": "Buy"}]}
{"table": "orderBookL2", "action": "insert", "data": [{"symbol": "XBTUSD", "id": 15597673200, "side": "Sell", "size": 544, "price": 23268}, {"symbol": "XBTUSD", "id": 15599826900, "side": "Buy", "size": 911, "price": 1731}]}
{"table": "orderBookL2", "action": "delete", "data": [{"symbol": "XBTUSD", "id": 15595794300, "side": "Sell"}, {"symbol": "XBTUSD", "id": 15599753500, "side": "Buy"}]}
{"table": "orderBookL2", "action": "insert", "data": [{"symbol": "XBTUSD", "id": 15598507900, "side": "Sell", "size": 313, "price": 14921}, {"symbol": "XBTUSD", "id": 15599807700, "side": "Buy", "size": 475, "price": 1923}]}
{"table": "orderBookL2", "action": "delete", "data": [{"symbol": "XBTUSD", "id": 15599057500, "side": "Sell"}]}
{"table": "orderBookL2", "action": "update", "data": [{"symbol": "XBTUSD", "id": 15599065000, "side": "Sell", "size": 656}]}
{"table": "orderBookL2", "action": "update", "data": [{"symbol": "XBTUSD", "id": 15599113750, "side": "Sell", "size": 35}]}
{"table": "orderBookL2", "action": "delete", "data": [{"symbol": "XBTUSD", "id": 15597673200, "side": "Sell"}, {"symbol": "XBTUSD", "id": 15599826900, "side": "Buy"}]}
{"table": "orderBookL2", "action": "insert", "data": [{"symbol": "XBTUSD", "id": 15597343500, "side": "Sell", "size": 574, "price": 26565}, {"symbol": "XBTUSD", "id": 15599835900, "side": "Buy", "size": 266, "price": 1641}]}
{"table": "orderBookL2", "action": "delete", "data": [{"symbol": "XBTUSD", "id": 15598143100, "side": "Sell"}, {"symbol": "XBTUSD", "id": 15599837000, "side": "Buy"}]}
{"table": "orderBookL2", "action": "insert", "data": [{"symbol": "XBTUSD", "id": 15596447300, "side": "Sell", "size": 407, "price": 35527}, {"symbol": "XBTUSD", "id": 15599797700, "side": "Buy", "size": 392, "price": 2023}]}
{"table": "orderBookL2", "action": "insert", "data": [{"symbol": "XBTUSD", "id": 15599113300, "side": "Sell", "size": 46, "price": 8867}]}
{"table": "orderBookL2", "action": "delete", "data": [{"symbol": "XBTUSD", "id": 15598504600, "side": "Sell"}, {"symbol": "XBTUSD", "id": 15599843000, "side": "Buy"}]}
{"table": "orderBookL2", "action": "insert", "data": [{"symbol": "XBTUSD", "id": 15597397000, "side": "Sell", "size": 99, "price": 26030}, {"symbol": "XBTUSD", "id": 15599751200, "side": "Buy", "size": 475, "price": 2488}]}
{"table": "orderBookL2", "action": "delete", "data": [{"symbol": "XBTUSD", "id": 15597240000, "side": "Sell"}, {"symbol": "XBTUSD", "id": 15599774500, "side": "Buy"}]}
{"table": "orderBookL2", "action": "insert", "data": [{"symbol": "XBTUSD", "id": 15597120400, "side": "Sell", "size": 450, "price": 28796}, {"symbol": "XBTUSD", "id": 15599764100, "side": "Buy", "size": 304, "price": 2359}]}
{"table": "orderBookL2", "action": "update", "data": [{"symbol": "XBTUSD", "id": 15599113300, "side": "Sell", "size": 155}]}
{"table": "orderBookL2", "action": "update", "data": [{"symbol": "XBTUSD", "id": 15599117000, "side": "Buy", "size": 482}]}
{"table": "orderBookL2", "action": "delete", "data": [{"symbol": "XBTUSD", "id": 15599101850, "side": "Sell"}, {"symbol": "XBTUSD", "id": 15599104350, "side": "Sell"}, {"symbol": "XBTUSD", "id": 15599106850, "side": "Sell"}, {"symbol": "XBTUSD", "id": 15599109350, "side": "Sell"}, {"symbol": "XBTUSD", "id": 15599111850, "side": "Sell"}]}
{"table": "orderBookL2", "action": "update", "data": [{"symbol": "XBTUSD", "id": 15599099350, "side": "Sell", "size": 1838}, {"symbol": "XBTUSD", "id": 15599114350, "side": "Sell", "size": 40}]}
{"table": "orderBookL2", "action": "delete", "data": [{"symbol": "XBTUSD", "id": 15596447300, "side": "Sell"}, {"symbol": "XBTUSD", "id": 15599797700, "side": "Buy"}]}
{"table": "orderBookL2", "action": "insert", "data": [{"symbol": "XBTUSD", "id": 15598008000, "side": "Sell", "size": 401, "price": 19920}, {"symbol": "XBTUSD", "id": 15599760600, "side": "Buy", "size": 389, "price": 2394}]}
{"table": "orderBookL2", "action": "delete", "data": [{"symbol": "XBTUSD", "id": 15597397000, "side": "Sell"}, {"symbol": "XBTUSD", "id": 15599751200, "side": "Buy"}]}
{"table": "orderBookL2", "action": "insert", "data": [{"symbol": "XBTUSD", "id": 15597756200, "side": "Sell", "size": 918, "price": 22438}, {"symbol": "XBTUSD", "id": 15599756200, "side": "Buy", "size": 868, "price": 2438}]}
{"table": "orderBookL2", "action": "delete", "data": [{"symbol": "XBTUSD", "id": 15598008000, "side": "Sell"}, {"symbol": "XBTUSD", "id": 15599760600, "side": "Buy"}]}
{"table": "orderBookL2", "action": "insert", "data": [{"symbol": "XBTUSD", "id": 15596754800, "side": "Sell", "size": 937, "price": 32452}, {"symbol": "XBTUSD", "id": 15599769400, "side": "Buy", "size": 483, "price": 2306}]}
{"table": "orderBookL2", "action": "delete", "data": [{"symbol": "XBTUSD", "id": 15598507900, "side": "Sell"}, {"symbol": "XBTUSD", "id": 15599807700, "side": "Buy"}]}
{"table": "orderBookL2", "action": "insert", "data": [{"symbol": "XBTUSD", "id": 15596464800, "side": "Sell", "size": 484, "price": 35352}, {"symbol": "XBTUSD", "id": 15599833000, "side": "Buy", "size": 669, "price": 1670}]}
{"table": "orderBookL2", "action": "update", "data": [{"symbol": "XBTUSD", "id": 15599116200, "side": "Sell", "size": 3186}, {"symbol": "XBTUSD", "id": 15599116800, "side": "Sell", "size": 38}]}
{"table": "orderBookL2", "action": "delete", "data": [{"symbol": "XBTUSD", "id": 15597343500, "side": "Sell"}, {"symbol": "XBTUSD", "id": 15599835900, "side": "Buy"}]}
{"table": "orderBookL2", "action": "insert", "data": [{"symbol": "XBTUSD", "id": 15597160700, "side": "Sell", "size": 584, "price": 28393}, {"symbol": "XBTUSD", "id": 15599831100, "side": "Buy", "size": 539, "price": 1689}]}
{"table": "orderBookL2", "action": "update", "data": [{"symbol": "XBTUSD", "id": 15599116950, "side": "Buy", "size": 129343}]}
{"table": "orderBookL2", "action": "update", "data": [{"symbol": "XBTUSD", "id": 15599110000, "side": "Sell", "size": 11522}]}
{"table": "orderBookL2", "action": "delete", "data": [{"symbol": "XBTUSD", "id": 15596754800, "side": "Sell"}, {"symbol": "XBTUSD", "id": 15599769400, "side": "Buy"}]}
{"table": "orderBookL2", "action": "insert", "data": [{"symbol": "XBTUSD", "id": 15595711400, "side": "Sell", "size": 741, "price": 42886}, {"symbol": "XBTUSD", "id": 15599758900, "side": "Buy", "size": 338, "price": 2411}]}
{"table": "orderBookL2", "action": "delete", "data": [{"symbol": "XBTUSD", "id": 15596464800, "side": "Sell"}, {"symbol": "XBTUSD", "id": 15599833000, "side": "Buy"}]}
{"table": "orderBookL2", "action": "insert", "data": [{"symbol": "XBTUSD", "id": 15598949700, "side": "Sell", "size": 428, "price": 10503}, {"symbol": "XBTUSD", "id": 15599841100, "side": "Buy", "size": 690, "price": 1589}]}
{"table": "orderBookL2", "action": "delete", "data": [{"symbol": "XBTUSD", "id": 15598949700, "side": "Sell"}, {"symbol": "XBTUSD", "id": 15599841100, "side": "Buy"}]}
{"table": "orderBookL2", "action": "insert", "data": [{"symbol": "XBTUSD", "id": 15595409500, "side": "Sell", "size": 558, "price": 45905}, {"symbol": "XBTUSD", "id": 15599759100, "side": "Buy", "size": 591, "price": 2409}]}
{"table": "orderBookL2", "action": "delete", "data": [{"symbol": "XBTUSD", "id": 15597120400, "side": "Sell"}, {"symbol": "XBTUSD", "id": 15599764100, "side": "Buy"}]}
{"table": "orderBookL2", "action": "insert", "data": [{"symbol": "XBTUSD", "id": 15597557000, "side": "Sell", "size": 531, "price": 24430}, {"symbol": "XBTUSD", "id": 15599826800, "side": "Buy", "size": 380, "price": 1732}]}
